<?xml version="1.0"?>
<robot xmlns:xacro="http://www.ros.org/wiki/xacro">

    <xacro:macro name="link_wheel" params="name">
        <link name="${name}">
            <inertial>
              <mass value="0.5"/>
              <origin rpy="0 1.5707 1.5707" xyz="0 0 0"/>
              <inertia ixx="0.000526666666667" ixy="0" ixz="0" iyy="0.000526666666667" iyz="0" izz="0.001"/>
            </inertial>
            <collision name="link_right_wheel_collision">
              <origin rpy="0 1.5707 1.5707" xyz="0 0 0"/>
              <geometry>
                <cylinder length="0.045" radius="0.08"/>
              </geometry>
            </collision>
            <visual name="${name}_visual">
              <origin rpy="0 1.5707 1.5707" xyz="0 0 0"/>
              <geometry>
                <cylinder length="0.045" radius="0.08"/>
              </geometry>
            </visual>
        </link>
    </xacro:macro>

    <xacro:macro name="joint_wheel" params="name child origin_xyz">
      <joint name="${name}" type="continuous">
        <origin rpy="0 0 0" xyz="${origin_xyz}"/>
        <child link="${child}"/>
        <parent link="base_link"/>
        <axis rpy="0 0 0" xyz="0 1 0"/>
      </joint>
    </xacro:macro>

    <xacro:macro name="cylinder_inertia" params="mass r l">
      <inertia  ixx="${mass*(3*r*r+l*l)/12}" ixy = "0" ixz = "0"
                iyy="${mass*(3*r*r+l*l)/12}" iyz = "0"
                izz="${mass*(r*r)/2}" />
    </xacro:macro>

    <xacro:macro name="vertical_support" params="number x y">
      <link name="support_${number}">
        <inertial>
          <mass value="0.1"/>
          <origin xyz="0 0 0" rpy="0 0 0"/>
          <inertia ixx="0.000526666666667" ixy="0" ixz="0" iyy="0.000526666666667" iyz="0" izz="0.001"/>
        </inertial>
        <collision name="vertical_support_${number}_collision">
          <origin xyz="0 0 0" rpy="0 0 0"/>
          <geometry>
            <box size="0.04 0.04 0.12"/>
          </geometry>
        </collision>
        <visual name="support_${number}_visual">
          <origin xyz="0 0 0" rpy="0 0 0"/>
          <geometry>
            <box size="0.04 0.04 0.12"/>
          </geometry>
        </visual>
      </link>

      <joint name="support_${number}_joint" type="fixed">
        <axis xyz="0 0 1" />
        <origin rpy="0 0 0" xyz="${x} ${y} 0.07"/>
        <parent link="base_link"/>
        <child link="support_${number}"/>
      </joint>
    </xacro:macro>


  </robot>